Workbook

Sheet Problem Statement
A1: Scenario
A2: You work at a small online store. You receive a messy raw export from the order management system every month. Your job: clean it, analyze it, and build a live-ish dashboard for the manager.
A4: Dataset to build
A5: Sheet: RawOrders — OrderID (format: "ORD-2024-00123"), CustomerName (mixed case, extra spaces), ProductCode, Category, OrderDate (some as text "15-Jan-2024"), Qty, UnitPrice, DiscountCode, ShipDate
A6: Sheet: Discounts — DiscountCode, DiscountPct
A7: 200 rows, 8 product categories, deliberate data quality issues
A9: Tasks | B9: Status
A10: Use TRIM, PROPER, TEXTSPLIT, MID, FIND to clean CustomerName and extract the numeric order number from OrderID. | B10: Done
A11: Convert text-format dates to real dates using DATEVALUE; extract Month, Weekday, Hour-of-day columns. | B11: Done
A12: Use XLOOKUP to pull discount %, then calculate FinalRevenue = Qty × UnitPrice × (1 − Discount%). | B12: Done
A13: Build an array formula that returns total revenue per category without a pivot table. | B13: Done
A14: Use TEXTJOIN to create a "Customer Order Summary" string: "CustomerName ordered X items across Y categories". | B14: Done
A15: Use COUNTIF by hour to find peak order hours and chart it as a line chart. | B15: Done
A16: Build a Pivot Table + Pivot Chart: Revenue by Category by Month, with a timeline slicer. | B16: Done
A17: Use Power Query to load RawOrders, clean the date column, remove duplicates, and merge with Discounts table.
A18: Add a FORECAST.ETS to project next 3 months of revenue based on historical monthly totals. | B18: Done

Sheet RawOrders
A1: OrderID | B1: CustomerName | C1: ProductCode | D1: ProductName | E1: Category | F1: OrderDateTime | G1: Qty | H1: UnitPrice | I1: DiscountCode | J1: ShipDate
A2: ORD-2024-00143 | B2: SHREYA GHOSH | C2: E005 | D2: Bluetooth Speaker | E2: Electronics | F2: 45313.875 | G2: 5 | H2: 1599 | I2: VIP25 | J2: 45315
A3: ORD-2024-00114 | B3: Zara sinha | C3: S004 | D3: Dumbbell Set | E3: Sports | F3: 45378.792 | G3: 2 | H3: 2999 | I3: NONE | J3: 45381
A4: ORD-2024-00019 | B4: nitin Wagh | C4: C002 | D4: Denim Jeans | E4: Clothing | F4: 45295.583 | G4: 1 | H4: 1199 | I4: NONE | J4: 45300
A5: ORD-2024-00106 | B5: rekha BOSE | C5: S002 | D5: Resistance Bands | E5: Sports | F5: 45363.75 | G5: 2 | H5: 499 | I5: WELCOME15 | J5: 45367
A6: ORD-2024-00055 | B6: deepa DESAI | C6: T002 | D6: Puzzle 500pc | E6: Toys | F6: 45447.292 | G6: 1 | H6: 649 | I6: NONE | J6: 45448
A7: ORD-2024-00176 | B7: akash MISHRA | C7: T001 | D7: Building Blocks | E7: Toys | F7: 45319.458 | G7: 4 | H7: 899 | I7: NONE | J7: 45324
A8: ORD-2024-00026 | B8: nikhil Singh | C8: G002 | D8: Green Tea 50pk | E8: Grocery | F8: 45336.458 | G8: 2 | H8: 299 | I8: NONE | J8: 45339
A9: ORD-2024-00023 | B9: raj joshi | C9: B002 | D9: Python Basics | E9: Books | F9: 45353.625 | G9: 5 | H9: 399 | I9: FLASH20 | J9: 45357
A10: ORD-2024-00105 | B10: nikhil Shukla | C10: G003 | D10: Honey 500g | E10: Grocery | F10: 45407.458 | G10: 5 | H10: 349 | I10: NONE | J10: 45411
A11: ORD-2024-00093 | B11: VARUN Mehta | C11: BT001 | D11: Face Wash | E11: Beauty | F11: 45322.5 | G11: 2 | H11: 249 | I11: NONE | J11: 45327
A12: ORD-2024-00015 | B12: raj joshi | C12: S002 | D12: Resistance Bands | E12: Sports | F12: 45393.333 | G12: 3 | H12: 499 | I12: NONE | J12: 45395
A13: ORD-2024-00194 | B13: leena dubey | C13: G005 | D13: Dark Chocolate | E13: Grocery | F13: 45352.667 | G13: 5 | H13: 199 | I13: NONE | J13: 45354
... A201: ORD-2024-00017 | B201: RIYA bhatnagar | C201: C005 | D201: Track Pants | E201: Clothing | F201: 45382.375 | G201: 1 | H201: 699 | I201: NONE | J201: 45384

Sheet Discounts
A1: DiscountCode | B1: DiscountPct
A2: SAVE10 | B2: 10
A3: FLASH20 | B3: 20
A4: WELCOME15 | B4: 15
A5: VIP25 | B5: 25
A6: FESTIVE30 | B6: 30
A7: NONE | B7: 0

Sheet 1
A1: OrderID | B1: CustomerName | C1: Find (2024) | D1: Mid (Order No) | E1: Textsplit | G1: Proper | H1: Trim | I1: 2024
A2: ORD-2024-00143 | B2: SHREYA GHOSH | C2: =FIND($I$1,A2) -> 5 | D2: =MID(A2,10,5) -> 00143 | E2: {=_xlfn.TEXTSPLIT(B2," ")} -> SHREYA | F2: GHOSH | G2: =PROPER(B2) -> Shreya Ghosh | H2: =TRIM(B2) -> SHREYA GHOSH | J2: Use TRIM, PROPER, TEXTSPLIT, MID, FIND to clean CustomerName and extract the numeric order number from OrderID.
A3: ORD-2024-00114 | B3: Zara sinha | C3: =FIND($I$1,A3) -> 5 | D3: =MID(A3,10,5) -> 00114 | E3: {=_xlfn.TEXTSPLIT(B3," ")} -> Zara | F3: sinha | G3: =PROPER(B3) -> Zara Sinha | H3: =TRIM(B3) -> Zara sinha
A4: ORD-2024-00019 | B4: nitin Wagh | C4: =FIND($I$1,A4) -> 5 | D4: =MID(A4,10,5) -> 00019 | E4: {=_xlfn.TEXTSPLIT(B4," ")} -> nitin | F4: Wagh | G4: =PROPER(B4) -> Nitin Wagh | H4: =TRIM(B4) -> nitin Wagh
A5: ORD-2024-00106 | B5: rekha BOSE | C5: =FIND($I$1,A5) -> 5 | D5: =MID(A5,10,5) -> 00106 | E5: {=_xlfn.TEXTSPLIT(B5," ")} -> rekha | F5: BOSE | G5: =PROPER(B5) -> Rekha Bose | H5: =TRIM(B5) -> rekha BOSE
A6: ORD-2024-00055 | B6: deepa DESAI | C6: =FIND($I$1,A6) -> 5 | D6: =MID(A6,10,5) -> 00055 | E6: {=_xlfn.TEXTSPLIT(B6," ")} -> deepa | F6: DESAI | G6: =PROPER(B6) -> Deepa Desai | H6: =TRIM(B6) -> deepa DESAI
A7: ORD-2024-00176 | B7: akash MISHRA | C7: =FIND($I$1,A7) -> 5 | D7: =MID(A7,10,5) -> 00176 | E7: {=_xlfn.TEXTSPLIT(B7," ")} -> akash | F7: MISHRA | G7: =PROPER(B7) -> Akash Mishra | H7: =TRIM(B7) -> akash MISHRA
A8: ORD-2024-00026 | B8: nikhil Singh | C8: =FIND($I$1,A8) -> 5 | D8: =MID(A8,10,5) -> 00026 | E8: {=_xlfn.TEXTSPLIT(B8," ")} -> nikhil | F8: Singh | G8: =PROPER(B8) -> Nikhil Singh | H8: =TRIM(B8) -> nikhil Singh
A9: ORD-2024-00023 | B9: raj joshi | C9: =FIND($I$1,A9) -> 5 | D9: =MID(A9,10,5) -> 00023 | E9: {=_xlfn.TEXTSPLIT(B9," ")} -> raj | F9: joshi | G9: =PROPER(B9) -> Raj Joshi | H9: =TRIM(B9) -> raj joshi
A10: ORD-2024-00105 | B10: nikhil Shukla | C10: =FIND($I$1,A10) -> 5 | D10: =MID(A10,10,5) -> 00105 | E10: {=_xlfn.TEXTSPLIT(B10," ")} -> nikhil | F10: Shukla | G10: =PROPER(B10) -> Nikhil Shukla | H10: =TRIM(B10) -> nikhil Shukla
A11: ORD-2024-00093 | B11: VARUN Mehta | C11: =FIND($I$1,A11) -> 5 | D11: =MID(A11,10,5) -> 00093 | E11: {=_xlfn.TEXTSPLIT(B11," ")} -> VARUN | F11: Mehta | G11: =PROPER(B11) -> Varun Mehta | H11: =TRIM(B11) -> VARUN Mehta
A12: ORD-2024-00015 | B12: raj joshi | C12: =FIND($I$1,A12) -> 5 | D12: =MID(A12,10,5) -> 00015 | E12: {=_xlfn.TEXTSPLIT(B12," ")} -> raj | F12: joshi | G12: =PROPER(B12) -> Raj Joshi | H12: =TRIM(B12) -> raj joshi
A13: ORD-2024-00194 | B13: leena dubey | C13: =FIND($I$1,A13) -> 5 | D13: =MID(A13,10,5) -> 00194 | E13: {=_xlfn.TEXTSPLIT(B13," ")} -> leena | F13: dubey | G13: =PROPER(B13) -> Leena Dubey | H13: =TRIM(B13) -> leena dubey
A14: ORD-2024-00018 | B14: Amit SHINDE | C14: =FIND($I$1,A14) -> 5 | D14: =MID(A14,10,5) -> 00018 | E14: {=_xlfn.TEXTSPLIT(B14," ")} -> Amit | F14: SHINDE | G14: =PROPER(B14) -> Amit Shinde | H14: =TRIM(B14) -> Amit SHINDE
... A45: ORD-2024-00035 | B45: aarav AGARWAL | C45: =FIND($I$1,A45) -> 5 | D45: =MID(A45,10,5) -> 00035 | E45: {=_xlfn.TEXTSPLIT(B45," ")} -> aarav | F45: AGARWAL | G45: =PROPER(B45) -> Aarav Agarwal | H45: =TRIM(B45) -> aarav AGARWAL
A46: ORD-2024-00042 | B46: alok joshi | C46: =FIND($I$1,A46) -> 5 | D46: =MID(A46,10,5) -> 00042 | E46: {=_xlfn.TEXTSPLIT(B46," ")} -> #VALUE! | G46: =PROPER(B46) -> Alok Joshi | H46: =TRIM(B46) -> alok joshi
A47: ORD-2024-00013 | B47: akash MISHRA | C47: =FIND($I$1,A47) -> 5 | D47: =MID(A47,10,5) -> 00013 | E47: {=_xlfn.TEXTSPLIT(B47," ")} -> akash | F47: MISHRA | G47: =PROPER(B47) -> Akash Mishra | H47: =TRIM(B47) -> akash MISHRA
A48: ORD-2024-00070 | B48: nikhil trivedi | C48: =FIND($I$1,A48) -> 5 | D48: =MID(A48,10,5) -> 00070 | E48: {=_xlfn.TEXTSPLIT(B48," ")} -> nikhil | F48: trivedi | G48: =PROPER(B48) -> Nikhil Trivedi | H48: =TRIM(B48) -> nikhil trivedi
A49: ORD-2024-00074 | B49: jyoti joshi | C49: =FIND($I$1,A49) -> 5 | D49: =MID(A49,10,5) -> 00074 | E49: {=_xlfn.TEXTSPLIT(B49," ")} -> jyoti | F49: joshi | G49: =PROPER(B49) -> Jyoti Joshi | H49: =TRIM(B49) -> jyoti joshi
A50: ORD-2024-00033 | B50: aarav AGARWAL | C50: =FIND($I$1,A50) -> 5 | D50: =MID(A50,10,5) -> 00033 | E50: {=_xlfn.TEXTSPLIT(B50," ")} -> aarav | F50: AGARWAL | G50: =PROPER(B50) -> Aarav Agarwal | H50: =TRIM(B50) -> aarav AGARWAL
A51: ORD-2024-00149 | B51: nikhil trivedi | C51: =FIND($I$1,A51) -> 5 | D51: =MID(A51,10,5) -> 00149 | E51: {=_xlfn.TEXTSPLIT(B51," ")} -> nikhil | F51: trivedi | G51: =PROPER(B51) -> Nikhil Trivedi | H51: =TRIM(B51) -> nikhil trivedi
A52: ORD-2024-00138 | B52: manav Bajaj | C52: =FIND($I$1,A52) -> 5 | D52: =MID(A52,10,5) -> 00138 | E52: {=_xlfn.TEXTSPLIT(B52," ")} -> manav | F52: Bajaj | G52: =PROPER(B52) -> Manav Bajaj | H52: =TRIM(B52) -> manav Bajaj
A53: ORD-2024-00195 | B53: Tanya Wagh | C53: =FIND($I$1,A53) -> 5 | D53: =MID(A53,10,5) -> 00195 | E53: {=_xlfn.TEXTSPLIT(B53," ")} -> Tanya | F53: Wagh | G53: =PROPER(B53) -> Tanya Wagh | H53: =TRIM(B53) -> Tanya Wagh
A54: ORD-2024-00027 | B54: SHREYA trivedi | C54: =FIND($I$1,A54) -> 5 | D54: =MID(A54,10,5) -> 00027 | E54: {=_xlfn.TEXTSPLIT(B54," ")} -> SHREYA | F54: trivedi | G54: =PROPER(B54) -> Shreya Trivedi | H54: =TRIM(B54) -> SHREYA trivedi
A55: ORD-2024-00072 | B55: RIYA bhatnagar | C55: =FIND($I$1,A55) -> 5 | D55: =MID(A55,10,5) -> 00072 | E55: {=_xlfn.TEXTSPLIT(B55," ")} -> RIYA | F55: bhatnagar | G55: =PROPER(B55) -> Riya Bhatnagar | H55: =TRIM(B55) -> RIYA bhatnagar
A56: ORD-2024-00054 | B56: alok joshi | C56: =FIND($I$1,A56) -> 5 | D56: =MID(A56,10,5) -> 00054 | E56: {=_xlfn.TEXTSPLIT(B56," ")} -> #VALUE! | G56: =PROPER(B56) -> Alok Joshi | H56: =TRIM(B56) -> alok joshi
A57: ORD-2024-00092 | B57: siddharth jadhav | C57: =FIND($I$1,A57) -> 5 | D57: =MID(A57,10,5) -> 00092 | E57: {=_xlfn.TEXTSPLIT(B57," ")} -> siddharth | F57: jadhav | G57: =PROPER(B57) -> Siddharth Jadhav | H57: =TRIM(B57) -> siddharth jadhav
A58: ORD-2024-00117 | B58: PRIYA NAIR | C58: =FIND($I$1,A58) -> 5 | D58: =MID(A58,10,5) -> 00117 | E58: {=_xlfn.TEXTSPLIT(B58," ")} -> PRIYA | F58: NAIR | G58: =PROPER(B58) -> Priya Nair | H58: =TRIM(B58) -> PRIYA NAIR
A59: ORD-2024-00147 | B59: sneha shah | C59: =FIND($I$1,A59) -> 5 | D59: =MID(A59,10,5) -> 00147 | E59: {=_xlfn.TEXTSPLIT(B59," ")} -> sneha | F59: shah | G59: =PROPER(B59) -> Sneha Shah | H59: =TRIM(B59) -> sneha shah
A60: ORD-2024-00163 | B60: saurav BOSE | C60: =FIND($I$1,A60) -> 5 | D60: =MID(A60,10,5) -> 00163 | E60: {=_xlfn.TEXTSPLIT(B60," ")} -> saurav | F60: BOSE | G60: =PROPER(B60) -> Saurav Bose | H60: =TRIM(B60) -> saurav BOSE
A61: ORD-2024-00184 | B61: deepa DESAI | C61: =FIND($I$1,A61) -> 5 | D61: =MID(A61,10,5) -> 00184 | E61: {=_xlfn.TEXTSPLIT(B61," ")} -> deepa | F61: DESAI | G61: =PROPER(B61) -> Deepa Desai | H61: =TRIM(B61) -> deepa DESAI
A62: ORD-2024-00010 | B62: tarun pillai | C62: =FIND($I$1,A62) -> 5 | D62: =MID(A62,10,5) -> 00010 | E62: {=_xlfn.TEXTSPLIT(B62," ")} -> tarun | F62: pillai | G62: =PROPER(B62) -> Tarun Pillai | H62: =TRIM(B62) -> tarun pillai
A63: ORD-2024-00091 | B63: Rohan GUPTA | C63: =FIND($I$1,A63) -> 5 | D63: =MID(A63,10,5) -> 00091 | E63: {=_xlfn.TEXTSPLIT(B63," ")} -> Rohan | F63: GUPTA | G63: =PROPER(B63) -> Rohan Gupta | H63: =TRIM(B63) -> Rohan GUPTA
A64: ORD-2024-00171 | B64: anjali More | C64: =FIND($I$1,A64) -> 5 | D64: =MID(A64,10,5) -> 00171 | E64: {=_xlfn.TEXTSPLIT(B64," ")} -> anjali | F64: More | G64: =PROPER(B64) -> Anjali More | H64: =TRIM(B64) -> anjali More
A65: ORD-2024-00071 | B65: leena GAIKWAD | C65: =FIND($I$1,A65) -> 5 | D65: =MID(A65,10,5) -> 00071 | E65: {=_xlfn.TEXTSPLIT(B65," ")} -> leena | F65: GAIKWAD | G65: =PROPER(B65) -> Leena Gaikwad | H65: =TRIM(B65) -> leena GAIKWAD
A66: ORD-2024-00200 | B66: nikhil Singh | C66: =FIND($I$1,A66) -> 5 | D66: =MID(A66,10,5) -> 00200 | E66: {=_xlfn.TEXTSPLIT(B66," ")} -> nikhil | F66: Singh | G66: =PROPER(B66) -> Nikhil Singh | H66: =TRIM(B66) -> nikhil Singh
A67: ORD-2024-00178 | B67: simran Bajaj | C67: =FIND($I$1,A67) -> 5 | D67: =MID(A67,10,5) -> 00178 | E67: {=_xlfn.TEXTSPLIT(B67," ")} -> simran | F67: Bajaj | G67: =PROPER(B67) -> Simran Bajaj | H67: =TRIM(B67) -> simran Bajaj
A68: ORD-2024-00153 | B68: akash MISHRA | C68: =FIND($I$1,A68) -> 5 | D68: =MID(A68,10,5) -> 00153 | E68: {=_xlfn.TEXTSPLIT(B68," ")} -> akash | F68: MISHRA | G68: =PROPER(B68) -> Akash Mishra | H68: =TRIM(B68) -> akash MISHRA
... A88: ORD-2024-00177 | B88: anjali More | C88: =FIND($I$1,A88) -> 5 | D88: =MID(A88,10,5) -> 00177 | E88: {=_xlfn.TEXTSPLIT(B88," ")} -> anjali | F88: More | G88: =PROPER(B88) -> Anjali More | H88: =TRIM(B88) -> anjali More
A89: ORD-2024-00151 | B89: alok joshi | C89: =FIND($I$1,A89) -> 5 | D89: =MID(A89,10,5) -> 00151 | E89: {=_xlfn.TEXTSPLIT(B89," ")} -> #VALUE! | G89: =PROPER(B89) -> Alok Joshi | H89: =TRIM(B89) -> alok joshi
...

Sheet 2
A1: OrderDateTime | B1: Month | C1: Weekday | D1: Hour of day
A2: 45313.875 | B2: =MONTH(A2) -> 1 | C2: =WEEKDAY(A2) -> 2 | D2: =HOUR(A2) -> 21 | F2: Convert text-format dates to real dates using DATEVALUE; extract Month, Weekday, Hour-of-day columns.
A3: 45378.792 | B3: =MONTH(A3) -> 3 | C3: =WEEKDAY(A3) -> 4 | D3: =HOUR(A3) -> 19
A4: 45295.583 | B4: =MONTH(A4) -> 1 | C4: =WEEKDAY(A4) -> 5 | D4: =HOUR(A4) -> 14
A5: 45363.75 | B5: =MONTH(A5) -> 3 | C5: =WEEKDAY(A5) -> 3 | D5: =HOUR(A5) -> 18
A6: 45447.292 | B6: =MONTH(A6) -> 6 | C6: =WEEKDAY(A6) -> 3 | D6: =HOUR(A6) -> 7
A7: 45319.458 | B7: =MONTH(A7) -> 1 | C7: =WEEKDAY(A7) -> 1 | D7: =HOUR(A7) -> 11
A8: 45336.458 | B8: =MONTH(A8) -> 2 | C8: =WEEKDAY(A8) -> 4 | D8: =HOUR(A8) -> 11
A9: 45353.625 | B9: =MONTH(A9) -> 3 | C9: =WEEKDAY(A9) -> 7 | D9: =HOUR(A9) -> 15
A10: 45407.458 | B10: =MONTH(A10) -> 4 | C10: =WEEKDAY(A10) -> 5 | D10: =HOUR(A10) -> 11
A11: 45322.5 | B11: =MONTH(A11) -> 1 | C11: =WEEKDAY(A11) -> 4 | D11: =HOUR(A11) -> 12
A12: 45393.333 | B12: =MONTH(A12) -> 4 | C12: =WEEKDAY(A12) -> 5 | D12: =HOUR(A12) -> 8
A13: 45352.667 | B13: =MONTH(A13) -> 3 | C13: =WEEKDAY(A13) -> 6 | D13: =HOUR(A13) -> 16
A14: 45351.5 | B14: =MONTH(A14) -> 2 | C14: =WEEKDAY(A14) -> 5 | D14: =HOUR(A14) -> 12
... A201: 45382.375 | B201: =MONTH(A201) -> 3 | C201: =WEEKDAY(A201) -> 1 | D201: =HOUR(A201) -> 9

Sheet 3
A1: CustomerName | B1: Qty | C1: UnitPrice | D1: DiscountCode | E1: Discount % | F1: Final Revenue | G1: Use XLOOKUP to pull discount %, then calculate FinalRevenue = Qty × UnitPrice × (1 − Discount%).
A2: SHREYA GHOSH | B2: 5 | C2: 1599 | D2: VIP25 | E2: =_xlfn.XLOOKUP(D2,Discounts!$A$2:$A$7,Discounts!$B$2:$B$7)/100 -> 0.25 | F2: =B2*C2*(1-E2) -> 5996.25
A3: Zara sinha | B3: 2 | C3: 2999 | D3: NONE | E3: =_xlfn.XLOOKUP(D3,Discounts!$A$2:$A$7,Discounts!$B$2:$B$7)/100 -> 0 | F3: =B3*C3*(1-E3) -> 5998
A4: nitin Wagh | B4: 1 | C4: 1199 | D4: NONE | E4: =_xlfn.XLOOKUP(D4,Discounts!$A$2:$A$7,Discounts!$B$2:$B$7)/100 -> 0 | F4: =B4*C4*(1-E4) -> 1199
A5: rekha BOSE | B5: 2 | C5: 499 | D5: WELCOME15 | E5: =_xlfn.XLOOKUP(D5,Discounts!$A$2:$A$7,Discounts!$B$2:$B$7)/100 -> 0.15 | F5: =B5*C5*(1-E5) -> 848.3
A6: deepa DESAI | B6: 1 | C6: 649 | D6: NONE | E6: =_xlfn.XLOOKUP(D6,Discounts!$A$2:$A$7,Discounts!$B$2:$B$7)/100 -> 0 | F6: =B6*C6*(1-E6) -> 649
A7: akash MISHRA | B7: 4 | C7: 899 | D7: NONE | E7: =_xlfn.XLOOKUP(D7,Discounts!$A$2:$A$7,Discounts!$B$2:$B$7)/100 -> 0 | F7: =B7*C7*(1-E7) -> 3596
A8: nikhil Singh | B8: 2 | C8: 299 | D8: NONE | E8: =_xlfn.XLOOKUP(D8,Discounts!$A$2:$A$7,Discounts!$B$2:$B$7)/100 -> 0 | F8: =B8*C8*(1-E8) -> 598
A9: raj joshi | B9: 5 | C9: 399 | D9: FLASH20 | E9: =_xlfn.XLOOKUP(D9,Discounts!$A$2:$A$7,Discounts!$B$2:$B$7)/100 -> 0.2 | F9: =B9*C9*(1-E9) -> 1596
A10: nikhil Shukla | B10: 5 | C10: 349 | D10: NONE | E10: =_xlfn.XLOOKUP(D10,Discounts!$A$2:$A$7,Discounts!$B$2:$B$7)/100 -> 0 | F10: =B10*C10*(1-E10) -> 1745
A11: VARUN Mehta | B11: 2 | C11: 249 | D11: NONE | E11: =_xlfn.XLOOKUP(D11,Discounts!$A$2:$A$7,Discounts!$B$2:$B$7)/100 -> 0 | F11: =B11*C11*(1-E11) -> 498
A12: raj joshi | B12: 3 | C12: 499 | D12: NONE | E12: =_xlfn.XLOOKUP(D12,Discounts!$A$2:$A$7,Discounts!$B$2:$B$7)/100 -> 0 | F12: =B12*C12*(1-E12) -> 1497
A13: leena dubey | B13: 5 | C13: 199 | D13: NONE | E13: =_xlfn.XLOOKUP(D13,Discounts!$A$2:$A$7,Discounts!$B$2:$B$7)/100 -> 0 | F13: =B13*C13*(1-E13) -> 995
... A201: RIYA bhatnagar | B201: 1 | C201: 699 | D201: NONE | E201: =_xlfn.XLOOKUP(D201,Discounts!$A$2:$A$7,Discounts!$B$2:$B$7)/100 -> 0 | F201: =B201*C201*(1-E201) -> 699

Sheet 4
A1: Category | B1: Qty | C1: UnitPrice | D1: Total Revenue | L1: Build an array formula that returns total revenue per category without a pivot table.
A2: Beauty | B2: 2 | C2: 249 | D2: =C2*B2 -> 498 | F2: Category | G2: Qty | H2: UnitPrice | I2: Total Revenue
A3: Beauty | B3: 5 | C3: 349 | D3: =C3*B3 -> 1745 | F3: {=_xlfn.UNIQUE(A2:A201)} -> Beauty | G3: =SUMIF($A$2:$A$201,F3,$B$2:$B$201) -> 59 | H3: =SUMIF($A$2:$A$201,F3,$C$2:$C$201) -> 7178 | I3: =G3*H3 -> 423502
A4: Beauty | B4: 3 | C4: 599 | D4: =C4*B4 -> 1797 | F4: Books | G4: =SUMIF($A$2:$A$201,F4,$B$2:$B$201) -> 52 | H4: =SUMIF($A$2:$A$201,F4,$C$2:$C$201) -> 7731 | I4: =G4*H4 -> 402012
A5: Beauty | B5: 1 | C5: 249 | D5: =C5*B5 -> 249 | F5: Clothing | G5: =SUMIF($A$2:$A$201,F5,$B$2:$B$201) -> 75 | H5: =SUMIF($A$2:$A$201,F5,$C$2:$C$201) -> 21675 | I5: =G5*H5 -> 1625625
A6: Beauty | B6: 4 | C6: 249 | D6: =C6*B6 -> 996 | F6: Electronics | G6: =SUMIF($A$2:$A$201,F6,$B$2:$B$201) -> 70 | H6: =SUMIF($A$2:$A$201,F6,$C$2:$C$201) -> 25374 | I6: =G6*H6 -> 1776180
A7: Beauty | B7: 2 | C7: 599 | D7: =C7*B7 -> 1198 | F7: Grocery | G7: =SUMIF($A$2:$A$201,F7,$B$2:$B$201) -> 52 | H7: =SUMIF($A$2:$A$201,F7,$C$2:$C$201) -> 6577 | I7: =G7*H7 -> 342004
A8: Beauty | B8: 1 | C8: 399 | D8: =C8*B8 -> 399 | F8: Home & Kitchen | G8: =SUMIF($A$2:$A$201,F8,$B$2:$B$201) -> 60 | H8: =SUMIF($A$2:$A$201,F8,$C$2:$C$201) -> 8525 | I8: =G8*H8 -> 511500
A9: Beauty | B9: 1 | C9: 349 | D9: =C9*B9 -> 349 | F9: Sports | G9: =SUMIF($A$2:$A$201,F9,$B$2:$B$201) -> 115 | H9: =SUMIF($A$2:$A$201,F9,$C$2:$C$201) -> 33964 | I9: =G9*H9 -> 3905860
A10: Beauty | B10: 5 | C10: 99 | D10: =C10*B10 -> 495 | F10: Toys | G10: =SUMIF($A$2:$A$201,F10,$B$2:$B$201) -> 68 | H10: =SUMIF($A$2:$A$201,F10,$C$2:$C$201) -> 15276 | I10: =G10*H10 -> 1038768
A11: Beauty | B11: 4 | C11: 349 | D11: =C11*B11 -> 1396
A12: Beauty | B12: 1 | C12: 99 | D12: =C12*B12 -> 99
A13: Beauty | B13: 2 | C13: 599 | D13: =C13*B13 -> 1198
A14: Beauty | B14: 2 | C14: 99 | D14: =C14*B14 -> 198
A15: Beauty | B15: 5 | C15: 399 | D15: =C15*B15 -> 1995
A16: Beauty | B16: 1 | C16: 349 | D16: =C16*B16 -> 349
A17: Beauty | B17: 1 | C17: 399 | D17: =C17*B17 -> 399
A18: Beauty | B18: 2 | C18: 249 | D18: =C18*B18 -> 498
A19: Beauty | B19: 4 | C19: 349 | D19: =C19*B19 -> 1396
A20: Beauty | B20: 3 | C20: 599 | D20: =C20*B20 -> 1797
A21: Beauty | B21: 4 | C21: 99 | D21: =C21*B21 -> 396
A22: Beauty | B22: 2 | C22: 349 | D22: =C22*B22 -> 698
... A201: Toys | B201: 1 | C201: 349 | D201: =C201*B201 -> 349

Sheet 5
A1: CustomerName | B1: ProductName | C1: Category | D1: Customer order summary
A2: SHREYA GHOSH | B2: Bluetooth Speaker | C2: Electronics | D2: =_xlfn.TEXTJOIN(" ",TRUE,A2," ordered ",B2,"Item across",C2,"category.") -> SHREYA GHOSH ordered Bluetooth Speaker Item across Electronics category. | G2: Use TEXTJOIN to create a "Customer Order Summary" string: "CustomerName ordered X items across Y categories".
A3: Zara sinha | B3: Dumbbell Set | C3: Sports | D3: =_xlfn.TEXTJOIN(" ",TRUE,A3," ordered ",B3,"Item across",C3,"category.") -> Zara sinha ordered Dumbbell Set Item across Sports category.
A4: nitin Wagh | B4: Denim Jeans | C4: Clothing | D4: =_xlfn.TEXTJOIN(" ",TRUE,A4," ordered ",B4,"Item across",C4,"category.") -> nitin Wagh ordered Denim Jeans Item across Clothing category.
A5: rekha BOSE | B5: Resistance Bands | C5: Sports | D5: =_xlfn.TEXTJOIN(" ",TRUE,A5," ordered ",B5,"Item across",C5,"category.") -> rekha BOSE ordered Resistance Bands Item across Sports category.
A6: deepa DESAI | B6: Puzzle 500pc | C6: Toys | D6: =_xlfn.TEXTJOIN(" ",TRUE,A6," ordered ",B6,"Item across",C6,"category.") -> deepa DESAI ordered Puzzle 500pc Item across Toys category.
A7: akash MISHRA | B7: Building Blocks | C7: Toys | D7: =_xlfn.TEXTJOIN(" ",TRUE,A7," ordered ",B7,"Item across",C7,"category.") -> akash MISHRA ordered Building Blocks Item across Toys category.
A8: nikhil Singh | B8: Green Tea 50pk | C8: Grocery | D8: =_xlfn.TEXTJOIN(" ",TRUE,A8," ordered ",B8,"Item across",C8,"category.") -> nikhil Singh ordered Green Tea 50pk Item across Grocery category.
A9: raj joshi | B9: Python Basics | C9: Books | D9: =_xlfn.TEXTJOIN(" ",TRUE,A9," ordered ",B9,"Item across",C9,"category.") -> raj joshi ordered Python Basics Item across Books category.
A10: nikhil Shukla | B10: Honey 500g | C10: Grocery | D10: =_xlfn.TEXTJOIN(" ",TRUE,A10," ordered ",B10,"Item across",C10,"category.") -> nikhil Shukla ordered Honey 500g Item across Grocery category.
A11: VARUN Mehta | B11: Face Wash | C11: Beauty | D11: =_xlfn.TEXTJOIN(" ",TRUE,A11," ordered ",B11,"Item across",C11,"category.") -> VARUN Mehta ordered Face Wash Item across Beauty category.
A12: raj joshi | B12: Resistance Bands | C12: Sports | D12: =_xlfn.TEXTJOIN(" ",TRUE,A12," ordered ",B12,"Item across",C12,"category.") -> raj joshi ordered Resistance Bands Item across Sports category.
A13: leena dubey | B13: Dark Chocolate | C13: Grocery | D13: =_xlfn.TEXTJOIN(" ",TRUE,A13," ordered ",B13,"Item across",C13,"category.") -> leena dubey ordered Dark Chocolate Item across Grocery category.
A14: Amit SHINDE | B14: Bluetooth Speaker | C14: Electronics | D14: =_xlfn.TEXTJOIN(" ",TRUE,A14," ordered ",B14,"Item across",C14,"category.") -> Amit SHINDE ordered Bluetooth Speaker Item across Electronics category.
... A201: RIYA bhatnagar | B201: Track Pants | C201: Clothing | D201: =_xlfn.TEXTJOIN(" ",TRUE,A201," ordered ",B201,"Item across",C201,"category.") -> RIYA bhatnagar ordered Track Pants Item across Clothing category.

Sheet 6
A1: OrderDateTime | B1: Hours | C1: Frequency | D1: Hour | E1: Peak
A2: 45363.75 | B2: =HOUR(A2) -> 18 | C2: =COUNTIF($B$2:$B$201,B2) -> 18 | D2: {=_xlfn.UNIQUE(B2:B201)} -> 18 | E2: =COUNTIF($B$2:$B$201,D2) -> 18 | H2: Use COUNTIF by hour to find peak order hours and chart it as a line chart.
A3: 45352.667 | B3: =HOUR(A3) -> 16 | C3: =COUNTIF($B$2:$B$201,B3) -> 18 | D3: 16 | E3: =COUNTIF($B$2:$B$201,D3) -> 18
A4: 45390.75 | B4: =HOUR(A4) -> 18 | C4: =COUNTIF($B$2:$B$201,B4) -> 18 | D4: 19 | E4: =COUNTIF($B$2:$B$201,D4) -> 15
A5: 45473.75 | B5: =HOUR(A5) -> 18 | C5: =COUNTIF($B$2:$B$201,B5) -> 18 | D5: 9 | E5: =COUNTIF($B$2:$B$201,D5) -> 15
A6: 45347.75 | B6: =HOUR(A6) -> 18 | C6: =COUNTIF($B$2:$B$201,B6) -> 18 | D6: 13 | E6: =COUNTIF($B$2:$B$201,D6) -> 14
A7: 45394.667 | B7: =HOUR(A7) -> 16 | C7: =COUNTIF($B$2:$B$201,B7) -> 18 | D7: 7 | E7: =COUNTIF($B$2:$B$201,D7) -> 13
A8: 45298.667 | B8: =HOUR(A8) -> 16 | C8: =COUNTIF($B$2:$B$201,B8) -> 18 | D8: 21 | E8: =COUNTIF($B$2:$B$201,D8) -> 12
A9: 45312.667 | B9: =HOUR(A9) -> 16 | C9: =COUNTIF($B$2:$B$201,B9) -> 18 | D9: 15 | E9: =COUNTIF($B$2:$B$201,D9) -> 12
A10: 45453.667 | B10: =HOUR(A10) -> 16 | C10: =COUNTIF($B$2:$B$201,B10) -> 18 | D10: 12 | E10: =COUNTIF($B$2:$B$201,D10) -> 12
A11: 45310.75 | B11: =HOUR(A11) -> 18 | C11: =COUNTIF($B$2:$B$201,B11) -> 18 | D11: 8 | E11: =COUNTIF($B$2:$B$201,D11) -> 11
A12: 45305.75 | B12: =HOUR(A12) -> 18 | C12: =COUNTIF($B$2:$B$201,B12) -> 18 | D12: 20 | E12: =COUNTIF($B$2:$B$201,D12) -> 11
A13: 45335.667 | B13: =HOUR(A13) -> 16 | C13: =COUNTIF($B$2:$B$201,B13) -> 18 | D13: 11 | E13: =COUNTIF($B$2:$B$201,D13) -> 10
A14: 45370.75 | B14: =HOUR(A14) -> 18 | C14: =COUNTIF($B$2:$B$201,B14) -> 18 | D14: 22 | E14: =COUNTIF($B$2:$B$201,D14) -> 10
... A18: 45468.667 | B18: =HOUR(A18) -> 16 | C18: =COUNTIF($B$2:$B$201,B18) -> 18 | D18: 14 | E18: =COUNTIF($B$2:$B$201,D18) -> 4
A19: 45373.667 | B19: =HOUR(A19) -> 16 | C19: =COUNTIF($B$2:$B$201,B19) -> 18
A20: 45385.667 | B20: =HOUR(A20) -> 16 | C20: =COUNTIF($B$2:$B$201,B20) -> 18
A21: 45418.75 | B21: =HOUR(A21) -> 18 | C21: =COUNTIF($B$2:$B$201,B21) -> 18
A22: 45416.75 | B22: =HOUR(A22) -> 18 | C22: =COUNTIF($B$2:$B$201,B22) -> 18
A23: 45308.667 | B23: =HOUR(A23) -> 16 | C23: =COUNTIF($B$2:$B$201,B23) -> 18
A24: 45331.75 | B24: =HOUR(A24) -> 18 | C24: =COUNTIF($B$2:$B$201,B24) -> 18
A25: 45410.75 | B25: =HOUR(A25) -> 18 | C25: =COUNTIF($B$2:$B$201,B25) -> 18
A26: 45342.75 | B26: =HOUR(A26) -> 18 | C26: =COUNTIF($B$2:$B$201,B26) -> 18
A27: 45461.667 | B27: =HOUR(A27) -> 16 | C27: =COUNTIF($B$2:$B$201,B27) -> 18
A28: 45373.667 | B28: =HOUR(A28) -> 16 | C28: =COUNTIF($B$2:$B$201,B28) -> 18
A29: 45347.667 | B29: =HOUR(A29) -> 16 | C29: =COUNTIF($B$2:$B$201,B29) -> 18
A30: 45315.75 | B30: =HOUR(A30) -> 18 | C30: =COUNTIF($B$2:$B$201,B30) -> 18
... A201: 45347.583 | B201: =HOUR(A201) -> 14 | C201: =COUNTIF($B$2:$B$201,B201) -> 4

Sheet 7
A1: Category | B1: OrderDateTime | C1: Revenue | D1: Qty | E1: UnitPrice | J1: Build a Pivot Table + Pivot Chart: Revenue by Category by Month, with a timeline slicer.
A2: Home & Kitchen | B2: 45292.333 | C2: =D2*E2 -> 7995 | D2: 5 | E2: 1599
A3: Toys | B3: 45292.958 | C3: =D3*E3 -> 5998 | D3: 2 | E3: 2999
A4: Toys | B4: 45294.458 | C4: =D4*E4 -> 1199 | D4: 1 | E4: 1199
A5: Beauty | B5: 45295.333 | C5: =D5*E5 -> 998 | D5: 2 | E5: 499 | G5: Category | H5: OrderDateTime | I5: Sum of Revenue
A6: Clothing | B6: 45295.417 | C6: =D6*E6 -> 649 | D6: 1 | E6: 649 | G6: Beauty | I6: 18541
A7: Clothing | B7: 45295.583 | C7: =D7*E7 -> 3596 | D7: 4 | E7: 899 | G7: Books | I7: 21488
A8: Grocery | B8: 45297.333 | C8: =D8*E8 -> 598 | D8: 2 | E8: 299 | G8: Clothing | I8: 66325
A9: Beauty | B9: 45298.667 | C9: =D9*E9 -> 1995 | D9: 5 | E9: 399 | G9: Electronics | I9: 69480
A10: Beauty | B10: 45299.333 | C10: =D10*E10 -> 1745 | D10: 5 | E10: 349 | G10: Grocery | I10: 15398
A11: Grocery | B11: 45300.542 | C11: =D11*E11 -> 498 | D11: 2 | E11: 249 | G11: Home & Kitchen | I11: 20990
A12: Grocery | B12: 45301.5 | C12: =D12*E12 -> 1497 | D12: 3 | E12: 499 | G12: Sports | I12: 120085
A13: Home & Kitchen | B13: 45301.708 | C13: =D13*E13 -> 995 | D13: 5 | E13: 199 | G13: Toys | I13: 45482
A14: Toys | B14: 45301.75 | C14: =D14*E14 -> 1599 | D14: 1 | E14: 1599 | G14: Grand Total | I14: 377789
A15: Beauty | B15: 45303.542 | C15: =D15*E15 -> 349 | D15: 1 | E15: 349
A16: Home & Kitchen | B16: 45304.708 | C16: =D16*E16 -> 698 | D16: 2 | E16: 349
A17: Clothing | B17: 45305.75 | C17: =D17*E17 -> 11996 | D17: 4 | E17: 2999
A18: Sports | B18: 45305.833 | C18: =D18*E18 -> 5196 | D18: 4 | E18: 1299
A19: Electronics | B19: 45305.917 | C19: =D19*E19 -> 299 | D19: 1 | E19: 299
A20: Home & Kitchen | B20: 45306.292 | C20: =D20*E20 -> 1596 | D20: 4 | E20: 399
A21: Toys | B21: 45306.375 | C21: =D21*E21 -> 649 | D21: 1 | E21: 649
A22: Toys | B22: 45308.375 | C22: =D22*E22 -> 1745 | D22: 5 | E22: 349
A23: Home & Kitchen | B23: 45308.667 | C23: =D23*E23 -> 798 | D23: 2 | E23: 399
A24: Grocery | B24: 45309.375 | C24: =D24*E24 -> 995 | D24: 5 | E24: 199
A25: Sports | B25: 45309.625 | C25: =D25*E25 -> 1745 | D25: 5 | E25: 349
A26: Sports | B26: 45309.75 | C26: =D26*E26 -> 698 | D26: 2 | E26: 349
... A201: Electronics | B201: 45473.75 | C201: =D201*E201 -> 699 | D201: 1 | E201: 699

Sheet 8
A1: Use Power Query to load RawOrders, clean the date column, remove duplicates, and merge with Discounts table.

Sheet 9
A1: OrderDateTime | B1: Qty | C1: UnitPrice | D1: Revenue | E1: Forecast | G1: Add a FORECAST.ETS to project next 3 months of revenue based on historical monthly totals.
A2: 45292.333 | B2: 2 | C2: 299 | D2: =C2*B2 -> 598 | E2: 45292 | F2: =SUM(D2:D37) -> 56852
A3: 45292.958 | B3: 2 | C3: 899 | D3: =C3*B3 -> 1798 | E3: 45323 | F3: =SUM(D38:D79) -> 89277
A4: 45294.458 | B4: 2 | C4: 899 | D4: =C4*B4 -> 1798 | E4: 45352 | F4: =SUM(D80:D113) -> 85390
A5: 45295.333 | B5: 4 | C5: 249 | D5: =C5*B5 -> 996 | E5: 45383 | F5: =SUM(D114:D137) -> 40935
A6: 45295.417 | B6: 3 | C6: 1199 | D6: =C6*B6 -> 3597 | E6: 45413 | F6: =SUM(D138:D172) -> 42023
A7: 45295.583 | B7: 1 | C7: 1199 | D7: =C7*B7 -> 1199 | E7: 45444 | F7: =SUM(D173:D201) -> 63312
A8: 45297.333 | B8: 1 | C8: 299 | D8: =C8*B8 -> 299 | E8: 45474 | F8: {=FORECAST(E8,$F$2:$F$7,$E$2:$E$7)} -> 47618.794
A9: 45298.667 | B9: 1 | C9: 249 | D9: =C9*B9 -> 249 | E9: 45505 | F9: {=FORECAST(E9,$F$2:$F$7,$E$2:$E$7)} -> 43137.847
A10: 45299.333 | B10: 1 | C10: 349 | D10: =C10*B10 -> 349 | E10: 45536 | F10: {=FORECAST(E10,$F$2:$F$7,$E$2:$E$7)} -> 38656.9
A11: 45300.542 | B11: 1 | C11: 199 | D11: =C11*B11 -> 199
A12: 45301.5 | B12: 2 | C12: 299 | D12: =C12*B12 -> 598
A13: 45301.708 | B13: 3 | C13: 649 | D13: =C13*B13 -> 1947
A14: 45301.75 | B14: 4 | C14: 499 | D14: =C14*B14 -> 1996
A15: 45303.542 | B15: 5 | C15: 349 | D15: =C15*B15 -> 1745
A16: 45304.708 | B16: 4 | C16: 649 | D16: =C16*B16 -> 2596
A17: 45305.75 | B17: 2 | C17: 699 | D17: =C17*B17 -> 1398
A18: 45305.833 | B18: 3 | C18: 799 | D18: =C18*B18 -> 2397
A19: 45305.917 | B19: 5 | C19: 349 | D19: =C19*B19 -> 1745
A20: 45306.292 | B20: 2 | C20: 199 | D20: =C20*B20 -> 398
A21: 45306.375 | B21: 4 | C21: 649 | D21: =C21*B21 -> 2596
A22: 45308.375 | B22: 2 | C22: 349 | D22: =C22*B22 -> 698
... A201: 45473.75 | B201: 5 | C201: 349 | D201: =C201*B201 -> 1745
